<?xml version="1.0" ?>
<robot name="ayspot_a0">
<link name="dummy">
</link>
<link name="base_link">
  <inertial>
    <origin rpy="0 0 0" xyz="0.0 0.0 0.0"/>
    <mass value="2.4"/>
    <inertia ixx="0.0" ixy="0.0" ixz="0.0" iyy="0.0" iyz="0.0" izz="0.0"/>
  </inertial>
  <visual>
    <origin rpy="0 0 0" xyz="0 0 0"/>
    <geometry>
      <mesh filename="package://fusion2urdf/ayspot_a0/bin_stl/base_link_m-binary.stl"/>
    </geometry>
    <material name="silver">
      <color rgba="1 0 0 1"/>
    </material>
  </visual>
  <collision>
    <origin rpy="0 0 0" xyz="0 0 0"/>
    <geometry>
      <mesh filename="package://fusion2urdf/ayspot_a0/bin_stl/base_link_m-binary.stl"/>
    </geometry>
  </collision>
</link>
<joint name="dummy_joint" type="fixed">
  <parent link="dummy"/>
  <child link="base_link"/>
</joint>
<link name="LH_HIP_1">
  <inertial>
    <origin rpy="0 0 0" xyz="-0.04050999999999999 0.0052340000000000025 -5.499999999999998e-05"/>
    <mass value="0.459459"/>
    <inertia ixx="0.000547" ixy="-5e-06" ixz="-4.6e-05" iyy="0.000835" iyz="4.5e-05" izz="0.000447"/>
  </inertial>
  <visual>
    <origin rpy="0 0 0" xyz="0.1149 -0.064996 -0.000495"/>
    <geometry>
      <mesh filename="package://fusion2urdf/ayspot_a0/bin_stl/LH_HIP_1_m-binary.stl"/>
    </geometry>
    <material name="silver">
      <color rgba="1 0 0 1"/>
    </material>
  </visual>
  <collision>
    <origin rpy="0 0 0" xyz="0.1149 -0.064996 -0.000495"/>
    <geometry>
      <mesh filename="package://fusion2urdf/ayspot_a0/bin_stl/LH_HIP_1_m-binary.stl"/>
    </geometry>
  </collision>
</link>
<link name="LH_THIGH_1">
  <inertial>
    <origin rpy="0 0 0" xyz="2.9000000000001247e-05 0.04524399999999999 -0.013476"/>
    <mass value="0.768175"/>
    <inertia ixx="0.00206" ixy="-1e-06" ixz="0.003456" iyy="0.001853" iyz="-0.003113" izz="0.001041"/>
  </inertial>
  <visual>
    <origin rpy="0 0 0" xyz="0.1807 -0.086296 -0.000495"/>
    <geometry>
      <mesh filename="package://fusion2urdf/ayspot_a0/bin_stl/LH_THIGH_1_m-binary.stl"/>
    </geometry>
    <material name="silver">
      <color rgba="1 0 0 1"/>
    </material>
  </visual>
  <collision>
    <origin rpy="0 0 0" xyz="0.1807 -0.086296 -0.000495"/>
    <geometry>
      <mesh filename="package://fusion2urdf/ayspot_a0/bin_stl/LH_THIGH_1_m-binary.stl"/>
    </geometry>
  </collision>
</link>
<link name="LH_SHARK_1">
  <inertial>
    <origin rpy="0 0 0" xyz="0.006410000000000027 0.0 -0.07012199999999999"/>
    <mass value="0.192568"/>
    <inertia ixx="0.000926" ixy="-0.0" ixz="0.014403" iyy="0.000942" iyz="-0.01439" izz="3.5e-05"/>
  </inertial>
  <visual>
    <origin rpy="0 0 0" xyz="0.180742 -0.166126 0.149559"/>
    <geometry>
      <mesh filename="package://fusion2urdf/ayspot_a0/bin_stl/LH_SHARK_1_m-binary.stl"/>
    </geometry>
    <material name="silver">
      <color rgba="1 0 0 1"/>
    </material>
  </visual>
  <collision>
    <origin rpy="0 0 0" xyz="0.180742 -0.166126 0.149559"/>
    <geometry>
      <mesh filename="package://fusion2urdf/ayspot_a0/bin_stl/LH_SHARK_1_m-binary.stl"/>
    </geometry>
  </collision>
</link>
<link name="LH_FOOT_1">
  <inertial>
    <origin rpy="0 0 0" xyz="-0.00023300000000001098 0.0 -0.0009020000000000139"/>
    <mass value="0.05928"/>
    <inertia ixx="1.1e-05" ixy="-0.0" ixz="0.0068" iyy="1e-05" iyz="-0.0068" izz="1.1e-05"/>
  </inertial>
  <visual>
    <origin rpy="0 0 0" xyz="0.180726 -0.166126 0.329586"/>
    <geometry>
      <mesh filename="package://fusion2urdf/ayspot_a0/bin_stl/LH_FOOT_1_m-binary.stl"/>
    </geometry>
    <material name="silver">
      <color rgba="1 0 0 1"/>
    </material>
  </visual>
  <collision>
    <origin rpy="0 0 0" xyz="0.180726 -0.166126 0.329586"/>
    <geometry>
      <mesh filename="package://fusion2urdf/ayspot_a0/bin_stl/LH_FOOT_1_m-binary.stl"/>
    </geometry>
  </collision>
</link>
<link name="RH_HIP_1">
  <inertial>
    <origin rpy="0 0 0" xyz="-0.04050999999999999 -0.0052340000000000025 5.400000000000001e-05"/>
    <mass value="0.459459"/>
    <inertia ixx="0.000547" ixy="5e-06" ixz="-2.2e-05" iyy="0.000835" iyz="2.2e-05" izz="0.000447"/>
  </inertial>
  <visual>
    <origin rpy="0 0 0" xyz="0.1149 0.064996 -0.000495"/>
    <geometry>
      <mesh filename="package://fusion2urdf/ayspot_a0/bin_stl/RH_HIP_1_m-binary.stl"/>
    </geometry>
    <material name="silver">
      <color rgba="1 0 0 1"/>
    </material>
  </visual>
  <collision>
    <origin rpy="0 0 0" xyz="0.1149 0.064996 -0.000495"/>
    <geometry>
      <mesh filename="package://fusion2urdf/ayspot_a0/bin_stl/RH_HIP_1_m-binary.stl"/>
    </geometry>
  </collision>
</link>
<link name="RH_THIGH_1">
  <inertial>
    <origin rpy="0 0 0" xyz="-3.0000000000002247e-05 -0.04524399999999999 -0.013476"/>
    <mass value="0.768175"/>
    <inertia ixx="0.00206" ixy="-1e-06" ixz="0.000148" iyy="0.001852" iyz="-0.000491" izz="0.001041"/>
  </inertial>
  <visual>
    <origin rpy="0 0 0" xyz="0.1807 0.086296 -0.000495"/>
    <geometry>
      <mesh filename="package://fusion2urdf/ayspot_a0/bin_stl/RH_THIGH_1_m-binary.stl"/>
    </geometry>
    <material name="silver">
      <color rgba="1 0 0 1"/>
    </material>
  </visual>
  <collision>
    <origin rpy="0 0 0" xyz="0.1807 0.086296 -0.000495"/>
    <geometry>
      <mesh filename="package://fusion2urdf/ayspot_a0/bin_stl/RH_THIGH_1_m-binary.stl"/>
    </geometry>
  </collision>
</link>
<link name="RH_SHARK_1">
  <inertial>
    <origin rpy="0 0 0" xyz="0.006531000000000009 0.0 -0.07012199999999999"/>
    <mass value="0.192568"/>
    <inertia ixx="0.000926" ixy="-0.0" ixz="0.000338" iyy="0.000942" iyz="-0.000326" izz="3.5e-05"/>
  </inertial>
  <visual>
    <origin rpy="0 0 0" xyz="0.180658 0.166126 0.149559"/>
    <geometry>
      <mesh filename="package://fusion2urdf/ayspot_a0/bin_stl/RH_SHARK_1_m-binary.stl"/>
    </geometry>
    <material name="silver">
      <color rgba="1 0 0 1"/>
    </material>
  </visual>
  <collision>
    <origin rpy="0 0 0" xyz="0.180658 0.166126 0.149559"/>
    <geometry>
      <mesh filename="package://fusion2urdf/ayspot_a0/bin_stl/RH_SHARK_1_m-binary.stl"/>
    </geometry>
  </collision>
</link>
<link name="RH_FOOT_1">
  <inertial>
    <origin rpy="0 0 0" xyz="-0.00040000000000001146 0.0 -0.0008400000000000074"/>
    <mass value="0.059271"/>
    <inertia ixx="1.1e-05" ixy="-0.0" ixz="0.00029" iyy="1e-05" iyz="-0.00029" izz="1.1e-05"/>
  </inertial>
  <visual>
    <origin rpy="0 0 0" xyz="0.180521 0.166126 0.329586"/>
    <geometry>
      <mesh filename="package://fusion2urdf/ayspot_a0/bin_stl/RH_FOOT_1_m-binary.stl"/>
    </geometry>
    <material name="silver">
      <color rgba="1 0 0 1"/>
    </material>
  </visual>
  <collision>
    <origin rpy="0 0 0" xyz="0.180521 0.166126 0.329586"/>
    <geometry>
      <mesh filename="package://fusion2urdf/ayspot_a0/bin_stl/RH_FOOT_1_m-binary.stl"/>
    </geometry>
  </collision>
</link>
<link name="RF_HIP_1">
  <inertial>
    <origin rpy="0 0 0" xyz="0.04050999999999999 -0.0052340000000000025 -5.499999999999998e-05"/>
    <mass value="0.459459"/>
    <inertia ixx="0.000547" ixy="-5e-06" ixz="4.6e-05" iyy="0.000835" iyz="-4.5e-05" izz="0.000447"/>
  </inertial>
  <visual>
    <origin rpy="0 0 0" xyz="-0.1149 0.064996 -0.000495"/>
    <geometry>
      <mesh filename="package://fusion2urdf/ayspot_a0/bin_stl/RF_HIP_1_m-binary.stl"/>
    </geometry>
    <material name="silver">
      <color rgba="1 0 0 1"/>
    </material>
  </visual>
  <collision>
    <origin rpy="0 0 0" xyz="-0.1149 0.064996 -0.000495"/>
    <geometry>
      <mesh filename="package://fusion2urdf/ayspot_a0/bin_stl/RF_HIP_1_m-binary.stl"/>
    </geometry>
  </collision>
</link>
<link name="RF_SHARK_1">
  <inertial>
    <origin rpy="0 0 0" xyz="0.006531999999999982 0.0 -0.07012199999999999"/>
    <mass value="0.192568"/>
    <inertia ixx="0.000926" ixy="-0.0" ixz="-0.01495" iyy="0.000942" iyz="0.014963" izz="3.5e-05"/>
  </inertial>
  <visual>
    <origin rpy="0 0 0" xyz="-0.180742 0.166126 0.149559"/>
    <geometry>
      <mesh filename="package://fusion2urdf/ayspot_a0/bin_stl/RF_SHARK_1_m-binary.stl"/>
    </geometry>
    <material name="silver">
      <color rgba="1 0 0 1"/>
    </material>
  </visual>
  <collision>
    <origin rpy="0 0 0" xyz="-0.180742 0.166126 0.149559"/>
    <geometry>
      <mesh filename="package://fusion2urdf/ayspot_a0/bin_stl/RF_SHARK_1_m-binary.stl"/>
    </geometry>
  </collision>
</link>
<link name="RF_FOOT_1">
  <inertial>
    <origin rpy="0 0 0" xyz="-0.00023300000000001098 0.0 -0.0009020000000000139"/>
    <mass value="0.05928"/>
    <inertia ixx="1.1e-05" ixy="-0.0" ixz="-0.006794" iyy="1e-05" iyz="0.006794" izz="1.1e-05"/>
  </inertial>
  <visual>
    <origin rpy="0 0 0" xyz="-0.18088 0.166126 0.329586"/>
    <geometry>
      <mesh filename="package://fusion2urdf/ayspot_a0/bin_stl/RF_FOOT_1_m-binary.stl"/>
    </geometry>
    <material name="silver">
      <color rgba="1 0 0 1"/>
    </material>
  </visual>
  <collision>
    <origin rpy="0 0 0" xyz="-0.18088 0.166126 0.329586"/>
    <geometry>
      <mesh filename="package://fusion2urdf/ayspot_a0/bin_stl/RF_FOOT_1_m-binary.stl"/>
    </geometry>
  </collision>
</link>
<link name="LF_SHARK_1">
  <inertial>
    <origin rpy="0 0 0" xyz="0.006531999999999982 0.0 -0.07012199999999999"/>
    <mass value="0.192568"/>
    <inertia ixx="0.000926" ixy="0.0" ixz="-0.000891" iyy="0.000942" iyz="0.000904" izz="3.5e-05"/>
  </inertial>
  <visual>
    <origin rpy="0 0 0" xyz="-0.180658 -0.166126 0.149559"/>
    <geometry>
      <mesh filename="package://fusion2urdf/ayspot_a0/bin_stl/LF_SHARK_1_m-binary.stl"/>
    </geometry>
    <material name="silver">
      <color rgba="1 0 0 1"/>
    </material>
  </visual>
  <collision>
    <origin rpy="0 0 0" xyz="-0.180658 -0.166126 0.149559"/>
    <geometry>
      <mesh filename="package://fusion2urdf/ayspot_a0/bin_stl/LF_SHARK_1_m-binary.stl"/>
    </geometry>
  </collision>
</link>
<link name="LF_FOOT_1">
  <inertial>
    <origin rpy="0 0 0" xyz="-0.00023300000000001098 0.0 -0.0009020000000000139"/>
    <mass value="0.05928"/>
    <inertia ixx="1.1e-05" ixy="0.0" ixz="-0.000283" iyy="1e-05" iyz="0.000283" izz="1.1e-05"/>
  </inertial>
  <visual>
    <origin rpy="0 0 0" xyz="-0.180796 -0.166126 0.329586"/>
    <geometry>
      <mesh filename="package://fusion2urdf/ayspot_a0/bin_stl/LF_FOOT_1_m-binary.stl"/>
    </geometry>
    <material name="silver">
      <color rgba="1 0 0 1"/>
    </material>
  </visual>
  <collision>
    <origin rpy="0 0 0" xyz="-0.180796 -0.166126 0.329586"/>
    <geometry>
      <mesh filename="package://fusion2urdf/ayspot_a0/bin_stl/LF_FOOT_1_m-binary.stl"/>
    </geometry>
  </collision>
</link>
<link name="LF_HIP_1">
  <inertial>
    <origin rpy="0 0 0" xyz="0.04050999999999999 0.0052340000000000025 5.400000000000001e-05"/>
    <mass value="0.459459"/>
    <inertia ixx="0.000547" ixy="5e-06" ixz="2.2e-05" iyy="0.000835" iyz="-2.2e-05" izz="0.000447"/>
  </inertial>
  <visual>
    <origin rpy="0 0 0" xyz="-0.1149 -0.064996 -0.000495"/>
    <geometry>
      <mesh filename="package://fusion2urdf/ayspot_a0/bin_stl/LF_HIP_1_m-binary.stl"/>
    </geometry>
    <material name="silver">
      <color rgba="1 0 0 1"/>
    </material>
  </visual>
  <collision>
    <origin rpy="0 0 0" xyz="-0.1149 -0.064996 -0.000495"/>
    <geometry>
      <mesh filename="package://fusion2urdf/ayspot_a0/bin_stl/LF_HIP_1_m-binary.stl"/>
    </geometry>
  </collision>
</link>
<link name="LF_THIGH_1">
  <inertial>
    <origin rpy="0 0 0" xyz="3.0000000000002247e-05 0.04524399999999999 -0.013476"/>
    <mass value="0.768175"/>
    <inertia ixx="0.00206" ixy="-1e-06" ixz="-0.000148" iyy="0.001852" iyz="0.000491" izz="0.001041"/>
  </inertial>
  <visual>
    <origin rpy="0 0 0" xyz="-0.1807 -0.086296 -0.000495"/>
    <geometry>
      <mesh filename="package://fusion2urdf/ayspot_a0/bin_stl/LF_THIGH_1_m-binary.stl"/>
    </geometry>
    <material name="silver">
      <color rgba="1 0 0 1"/>
    </material>
  </visual>
  <collision>
    <origin rpy="0 0 0" xyz="-0.1807 -0.086296 -0.000495"/>
    <geometry>
      <mesh filename="package://fusion2urdf/ayspot_a0/bin_stl/LF_THIGH_1_m-binary.stl"/>
    </geometry>
  </collision>
</link>
<link name="RF_THIGH_1">
  <inertial>
    <origin rpy="0 0 0" xyz="-2.9000000000001247e-05 -0.04524399999999999 -0.013476"/>
    <mass value="0.768175"/>
    <inertia ixx="0.00206" ixy="-1e-06" ixz="-0.003456" iyy="0.001853" iyz="0.003113" izz="0.001041"/>
  </inertial>
  <visual>
    <origin rpy="0 0 0" xyz="-0.1807 0.086296 -0.000495"/>
    <geometry>
      <mesh filename="package://fusion2urdf/ayspot_a0/bin_stl/RF_THIGH_1_m-binary.stl"/>
    </geometry>
    <material name="silver">
      <color rgba="1 0 0 1"/>
    </material>
  </visual>
  <collision>
    <origin rpy="0 0 0" xyz="-0.1807 0.086296 -0.000495"/>
    <geometry>
      <mesh filename="package://fusion2urdf/ayspot_a0/bin_stl/RF_THIGH_1_m-binary.stl"/>
    </geometry>
  </collision>
</link>
<joint name="LH_HIP_rotate" type="continuous">
  <origin rpy="0 0 0" xyz="-0.1149 0.064996 0.000495"/>
  <parent link="base_link"/>
  <child link="LH_HIP_1"/>
  <axis xyz="0.01 0.0 0.0"/>
</joint>
<transmission name="LH_HIP_rotate_tran">
  <type>transmission_interface/SimpleTransmission</type>
  <joint name="LH_HIP_rotate">
    <hardwareInterface>PositionJointInterface</hardwareInterface>
  </joint>
  <actuator name="LH_HIP_rotate_actr">
    <hardwareInterface>PositionJointInterface</hardwareInterface>
    <mechanicalReduction>1</mechanicalReduction>
  </actuator>
</transmission>
<joint name="LH_THIGH_rotate" type="continuous">
  <origin rpy="0 0 0" xyz="-0.0658 0.0213 0.0"/>
  <parent link="LH_HIP_1"/>
  <child link="LH_THIGH_1"/>
  <axis xyz="0.0 0.01 0.0"/>
</joint>
<transmission name="LH_THIGH_rotate_tran">
  <type>transmission_interface/SimpleTransmission</type>
  <joint name="LH_THIGH_rotate">
    <hardwareInterface>PositionJointInterface</hardwareInterface>
  </joint>
  <actuator name="LH_THIGH_rotate_actr">
    <hardwareInterface>PositionJointInterface</hardwareInterface>
    <mechanicalReduction>1</mechanicalReduction>
  </actuator>
</transmission>
<joint name="LH_SHARK_rotate" type="continuous">
  <origin rpy="0 0 0" xyz="-4.2e-05 0.07983 -0.150054"/>
  <parent link="LH_THIGH_1"/>
  <child link="LH_SHARK_1"/>
  <axis xyz="0.0 0.01 0.0"/>
</joint>
<transmission name="LH_SHARK_rotate_tran">
  <type>transmission_interface/SimpleTransmission</type>
  <joint name="LH_SHARK_rotate">
    <hardwareInterface>PositionJointInterface</hardwareInterface>
  </joint>
  <actuator name="LH_SHARK_rotate_actr">
    <hardwareInterface>PositionJointInterface</hardwareInterface>
    <mechanicalReduction>1</mechanicalReduction>
  </actuator>
</transmission>
<joint name="LH_FOOT_rigid" type="fixed">
  <origin rpy="0 0 0" xyz="1.6e-05 0.0 -0.180027"/>
  <parent link="LH_SHARK_1"/>
  <child link="LH_FOOT_1"/>
</joint>
<transmission name="LH_FOOT_rigid_tran">
  <type>transmission_interface/SimpleTransmission</type>
  <joint name="LH_FOOT_rigid">
    <hardwareInterface>PositionJointInterface</hardwareInterface>
  </joint>
  <actuator name="LH_FOOT_rigid_actr">
    <hardwareInterface>PositionJointInterface</hardwareInterface>
    <mechanicalReduction>1</mechanicalReduction>
  </actuator>
</transmission>
<joint name="RH_HIP_rotate" type="continuous">
  <origin rpy="0 0 0" xyz="-0.1149 -0.064996 0.000495"/>
  <parent link="base_link"/>
  <child link="RH_HIP_1"/>
  <axis xyz="0.01 0.0 0.0"/>
</joint>
<transmission name="RH_HIP_rotate_tran">
  <type>transmission_interface/SimpleTransmission</type>
  <joint name="RH_HIP_rotate">
    <hardwareInterface>PositionJointInterface</hardwareInterface>
  </joint>
  <actuator name="RH_HIP_rotate_actr">
    <hardwareInterface>PositionJointInterface</hardwareInterface>
    <mechanicalReduction>1</mechanicalReduction>
  </actuator>
</transmission>
<joint name="RH_THIGH_rotate" type="continuous">
  <origin rpy="0 0 0" xyz="-0.0658 -0.0213 0.0"/>
  <parent link="RH_HIP_1"/>
  <child link="RH_THIGH_1"/>
  <axis xyz="0.0 0.01 0.0"/>
</joint>
<transmission name="RH_THIGH_rotate_tran">
  <type>transmission_interface/SimpleTransmission</type>
  <joint name="RH_THIGH_rotate">
    <hardwareInterface>PositionJointInterface</hardwareInterface>
  </joint>
  <actuator name="RH_THIGH_rotate_actr">
    <hardwareInterface>PositionJointInterface</hardwareInterface>
    <mechanicalReduction>1</mechanicalReduction>
  </actuator>
</transmission>
<joint name="RH_SHARK_rotate" type="continuous">
  <origin rpy="0 0 0" xyz="4.2e-05 -0.07983 -0.150054"/>
  <parent link="RH_THIGH_1"/>
  <child link="RH_SHARK_1"/>
  <axis xyz="0.0 0.01 0.0"/>
</joint>
<transmission name="RH_SHARK_rotate_tran">
  <type>transmission_interface/SimpleTransmission</type>
  <joint name="RH_SHARK_rotate">
    <hardwareInterface>PositionJointInterface</hardwareInterface>
  </joint>
  <actuator name="RH_SHARK_rotate_actr">
    <hardwareInterface>PositionJointInterface</hardwareInterface>
    <mechanicalReduction>1</mechanicalReduction>
  </actuator>
</transmission>
<joint name="RH_FOOT_rigid" type="fixed">
  <origin rpy="0 0 0" xyz="0.000137 0.0 -0.180027"/>
  <parent link="RH_SHARK_1"/>
  <child link="RH_FOOT_1"/>
</joint>
<transmission name="RH_FOOT_rigid_tran">
  <type>transmission_interface/SimpleTransmission</type>
  <joint name="RH_FOOT_rigid">
    <hardwareInterface>PositionJointInterface</hardwareInterface>
  </joint>
  <actuator name="RH_FOOT_rigid_actr">
    <hardwareInterface>PositionJointInterface</hardwareInterface>
    <mechanicalReduction>1</mechanicalReduction>
  </actuator>
</transmission>
<joint name="RF_HIP_rotate" type="continuous">
  <origin rpy="0 0 0" xyz="0.1149 -0.064996 0.000495"/>
  <parent link="base_link"/>
  <child link="RF_HIP_1"/>
  <axis xyz="0.01 0.0 0.0"/>
</joint>
<transmission name="RF_HIP_rotate_tran">
  <type>transmission_interface/SimpleTransmission</type>
  <joint name="RF_HIP_rotate">
    <hardwareInterface>PositionJointInterface</hardwareInterface>
  </joint>
  <actuator name="RF_HIP_rotate_actr">
    <hardwareInterface>PositionJointInterface</hardwareInterface>
    <mechanicalReduction>1</mechanicalReduction>
  </actuator>
</transmission>
<joint name="RF_SHARK_rotate" type="continuous">
  <origin rpy="0 0 0" xyz="4.2e-05 -0.07983 -0.150054"/>
  <parent link="RF_THIGH_1"/>
  <child link="RF_SHARK_1"/>
  <axis xyz="0.0 0.01 0.0"/>
</joint>
<transmission name="RF_SHARK_rotate_tran">
  <type>transmission_interface/SimpleTransmission</type>
  <joint name="RF_SHARK_rotate">
    <hardwareInterface>PositionJointInterface</hardwareInterface>
  </joint>
  <actuator name="RF_SHARK_rotate_actr">
    <hardwareInterface>PositionJointInterface</hardwareInterface>
    <mechanicalReduction>1</mechanicalReduction>
  </actuator>
</transmission>
<joint name="RF_FOOT_rigid" type="fixed">
  <origin rpy="0 0 0" xyz="0.000138 0.0 -0.180027"/>
  <parent link="RF_SHARK_1"/>
  <child link="RF_FOOT_1"/>
</joint>
<transmission name="RF_FOOT_rigid_tran">
  <type>transmission_interface/SimpleTransmission</type>
  <joint name="RF_FOOT_rigid">
    <hardwareInterface>PositionJointInterface</hardwareInterface>
  </joint>
  <actuator name="RF_FOOT_rigid_actr">
    <hardwareInterface>PositionJointInterface</hardwareInterface>
    <mechanicalReduction>1</mechanicalReduction>
  </actuator>
</transmission>
<joint name="LF_SHARK_rotate" type="continuous">
  <origin rpy="0 0 0" xyz="-4.2e-05 0.07983 -0.150054"/>
  <parent link="LF_THIGH_1"/>
  <child link="LF_SHARK_1"/>
  <axis xyz="0.0 0.01 0.0"/>
</joint>
<transmission name="LF_SHARK_rotate_tran">
  <type>transmission_interface/SimpleTransmission</type>
  <joint name="LF_SHARK_rotate">
    <hardwareInterface>PositionJointInterface</hardwareInterface>
  </joint>
  <actuator name="LF_SHARK_rotate_actr">
    <hardwareInterface>PositionJointInterface</hardwareInterface>
    <mechanicalReduction>1</mechanicalReduction>
  </actuator>
</transmission>
<joint name="LF_FOOT_rigid" type="fixed">
  <origin rpy="0 0 0" xyz="0.000138 0.0 -0.180027"/>
  <parent link="LF_SHARK_1"/>
  <child link="LF_FOOT_1"/>
</joint>
<transmission name="LF_FOOT_rigid_tran">
  <type>transmission_interface/SimpleTransmission</type>
  <joint name="LF_FOOT_rigid">
    <hardwareInterface>PositionJointInterface</hardwareInterface>
  </joint>
  <actuator name="LF_FOOT_rigid_actr">
    <hardwareInterface>PositionJointInterface</hardwareInterface>
    <mechanicalReduction>1</mechanicalReduction>
  </actuator>
</transmission>
<joint name="LF_HIP_rotate" type="continuous">
  <origin rpy="0 0 0" xyz="0.1149 0.064996 0.000495"/>
  <parent link="base_link"/>
  <child link="LF_HIP_1"/>
  <axis xyz="0.01 0.0 0.0"/>
</joint>
<transmission name="LF_HIP_rotate_tran">
  <type>transmission_interface/SimpleTransmission</type>
  <joint name="LF_HIP_rotate">
    <hardwareInterface>PositionJointInterface</hardwareInterface>
  </joint>
  <actuator name="LF_HIP_rotate_actr">
    <hardwareInterface>PositionJointInterface</hardwareInterface>
    <mechanicalReduction>1</mechanicalReduction>
  </actuator>
</transmission>
<joint name="LF_THIGH_rotate" type="continuous">
  <origin rpy="0 0 0" xyz="0.0658 0.0213 0.0"/>
  <parent link="LF_HIP_1"/>
  <child link="LF_THIGH_1"/>
  <axis xyz="-0.0 0.01 0.0"/>
</joint>
<transmission name="LF_THIGH_rotate_tran">
  <type>transmission_interface/SimpleTransmission</type>
  <joint name="LF_THIGH_rotate">
    <hardwareInterface>PositionJointInterface</hardwareInterface>
  </joint>
  <actuator name="LF_THIGH_rotate_actr">
    <hardwareInterface>PositionJointInterface</hardwareInterface>
    <mechanicalReduction>1</mechanicalReduction>
  </actuator>
</transmission>
<joint name="RF_THIGH_rotate" type="continuous">
  <origin rpy="0 0 0" xyz="0.0658 -0.0213 0.0"/>
  <parent link="RF_HIP_1"/>
  <child link="RF_THIGH_1"/>
  <axis xyz="0.0 0.01 0.0"/>
</joint>
<transmission name="RF_THIGH_rotate_tran">
  <type>transmission_interface/SimpleTransmission</type>
  <joint name="RF_THIGH_rotate">
    <hardwareInterface>PositionJointInterface</hardwareInterface>
  </joint>
  <actuator name="RF_THIGH_rotate_actr">
    <hardwareInterface>PositionJointInterface</hardwareInterface>
    <mechanicalReduction>1</mechanicalReduction>
  </actuator>
</transmission>
<gazebo>
  <plugin filename="libgazebo_ros_control.so" name="control"/>
</gazebo>
</robot>
