<?xml version="1.0" ?>
<robot name="ayspot_a0">
<link name="base_link">
  <inertial>
    <origin rpy="0 0 0" xyz="0.0 0.0 0.0"/>
    <mass value="0.0"/>
    <inertia ixx="0.0" ixy="0.0" ixz="0.0" iyy="0.0" iyz="0.0" izz="0.0"/>
  </inertial>
  <visual>
    <origin rpy="0 0 0" xyz="0 0 0"/>
    <geometry>
      <mesh filename="package://fusion2urdf/ayspot_a0/bin_stl/base_link_m-binary.stl"/>
    </geometry>
    <material name="silver">
      <color rgba="1 0 0 1"/>
    </material>
  </visual>
  <collision>
    <origin rpy="0 0 0" xyz="0 0 0"/>
    <geometry>
      <mesh filename="package://fusion2urdf/ayspot_a0/bin_stl/base_link_m-binary.stl"/>
    </geometry>
  </collision>
</link>
<link name="Hip_R_L_1">
  <inertial>
    <origin rpy="0 0 0" xyz="0.04050799999999999 -0.0052340000000000025 -5.499999999997174e-05"/>
    <mass value="1.335734"/>
    <inertia ixx="0.001589" ixy="-1.3e-05" ixz="0.103408" iyy="0.002428" iyz="-0.103406" izz="0.0013"/>
  </inertial>
  <visual>
    <origin rpy="0 0 0" xyz="-0.1124 0.064996 -0.346995"/>
    <geometry>
      <mesh filename="package://fusion2urdf/ayspot_a0/bin_stl/Hip_R_L_1_m-binary.stl"/>
    </geometry>
    <material name="silver">
      <color rgba="1 0 0 1"/>
    </material>
  </visual>
  <collision>
    <origin rpy="0 0 0" xyz="-0.1124 0.064996 -0.346995"/>
    <geometry>
      <mesh filename="package://fusion2urdf/ayspot_a0/bin_stl/Hip_R_L_1_m-binary.stl"/>
    </geometry>
  </collision>
</link>
<link name="Upper_R_L_1">
  <inertial>
    <origin rpy="0 0 0" xyz="-2.9000000000001247e-05 -0.04524399999999999 -0.013477000000000017"/>
    <mass value="2.23339"/>
    <inertia ixx="0.00599" ixy="-2e-06" ixz="0.229701" iyy="0.005387" iyz="-0.230698" izz="0.003026"/>
  </inertial>
  <visual>
    <origin rpy="0 0 0" xyz="-0.1782 0.086296 -0.346995"/>
    <geometry>
      <mesh filename="package://fusion2urdf/ayspot_a0/bin_stl/Upper_R_L_1_m-binary.stl"/>
    </geometry>
    <material name="silver">
      <color rgba="1 0 0 1"/>
    </material>
  </visual>
  <collision>
    <origin rpy="0 0 0" xyz="-0.1782 0.086296 -0.346995"/>
    <geometry>
      <mesh filename="package://fusion2urdf/ayspot_a0/bin_stl/Upper_R_L_1_m-binary.stl"/>
    </geometry>
  </collision>
</link>
<link name="Lower_R_L_1">
  <inertial>
    <origin rpy="0 0 0" xyz="-0.0062530000000000086 -2.0999999999993246e-05 -0.070108"/>
    <mass value="0.539373"/>
    <inertia ixx="0.00264" ixy="0.0" ixz="0.023133" iyy="0.002688" iyz="-0.023167" izz="9.6e-05"/>
  </inertial>
  <visual>
    <origin rpy="0 0 0" xyz="-0.178242 0.166126 -0.196941"/>
    <geometry>
      <mesh filename="package://fusion2urdf/ayspot_a0/bin_stl/Lower_R_L_1_m-binary.stl"/>
    </geometry>
    <material name="silver">
      <color rgba="1 0 0 1"/>
    </material>
  </visual>
  <collision>
    <origin rpy="0 0 0" xyz="-0.178242 0.166126 -0.196941"/>
    <geometry>
      <mesh filename="package://fusion2urdf/ayspot_a0/bin_stl/Lower_R_L_1_m-binary.stl"/>
    </geometry>
  </collision>
</link>
<link name="Hip_R_R_1">
  <inertial>
    <origin rpy="0 0 0" xyz="0.04050799999999999 0.0052340000000000025 5.3999999999998494e-05"/>
    <mass value="1.335734"/>
    <inertia ixx="0.001589" ixy="1.3e-05" ixz="0.038328" iyy="0.002428" iyz="-0.038327" izz="0.0013"/>
  </inertial>
  <visual>
    <origin rpy="0 0 0" xyz="-0.1124 -0.064996 -0.346995"/>
    <geometry>
      <mesh filename="package://fusion2urdf/ayspot_a0/bin_stl/Hip_R_R_1_m-binary.stl"/>
    </geometry>
    <material name="silver">
      <color rgba="1 0 0 1"/>
    </material>
  </visual>
  <collision>
    <origin rpy="0 0 0" xyz="-0.1124 -0.064996 -0.346995"/>
    <geometry>
      <mesh filename="package://fusion2urdf/ayspot_a0/bin_stl/Hip_R_R_1_m-binary.stl"/>
    </geometry>
  </collision>
</link>
<link name="Upper_R_R_1">
  <inertial>
    <origin rpy="0 0 0" xyz="3.0000000000002247e-05 0.04524399999999999 -0.013477000000000017"/>
    <mass value="2.23339"/>
    <inertia ixx="0.00599" ixy="-2e-06" ixz="0.035774" iyy="0.005386" iyz="-0.034777" izz="0.003026"/>
  </inertial>
  <visual>
    <origin rpy="0 0 0" xyz="-0.1782 -0.086296 -0.346995"/>
    <geometry>
      <mesh filename="package://fusion2urdf/ayspot_a0/bin_stl/Upper_R_R_1_m-binary.stl"/>
    </geometry>
    <material name="silver">
      <color rgba="1 0 0 1"/>
    </material>
  </visual>
  <collision>
    <origin rpy="0 0 0" xyz="-0.1782 -0.086296 -0.346995"/>
    <geometry>
      <mesh filename="package://fusion2urdf/ayspot_a0/bin_stl/Upper_R_R_1_m-binary.stl"/>
    </geometry>
  </collision>
</link>
<link name="Lower_R_R_1">
  <inertial>
    <origin rpy="0 0 0" xyz="-0.0062530000000000086 -2.1999999999994246e-05 -0.070108"/>
    <mass value="0.539373"/>
    <inertia ixx="0.00264" ixy="0.0" ixz="0.000398" iyy="0.002688" iyz="-0.000432" izz="9.6e-05"/>
  </inertial>
  <visual>
    <origin rpy="0 0 0" xyz="-0.178158 -0.166126 -0.196941"/>
    <geometry>
      <mesh filename="package://fusion2urdf/ayspot_a0/bin_stl/Lower_R_R_1_m-binary.stl"/>
    </geometry>
    <material name="silver">
      <color rgba="1 0 0 1"/>
    </material>
  </visual>
  <collision>
    <origin rpy="0 0 0" xyz="-0.178158 -0.166126 -0.196941"/>
    <geometry>
      <mesh filename="package://fusion2urdf/ayspot_a0/bin_stl/Lower_R_R_1_m-binary.stl"/>
    </geometry>
  </collision>
</link>
<link name="Hip_F_L_1">
  <inertial>
    <origin rpy="0 0 0" xyz="-0.04050799999999999 -0.0052340000000000025 5.3999999999998494e-05"/>
    <mass value="1.335734"/>
    <inertia ixx="0.001589" ixy="1.3e-05" ixz="-0.040645" iyy="0.002428" iyz="0.040645" izz="0.0013"/>
  </inertial>
  <visual>
    <origin rpy="0 0 0" xyz="0.1174 0.064996 -0.346995"/>
    <geometry>
      <mesh filename="package://fusion2urdf/ayspot_a0/bin_stl/Hip_F_L_1_m-binary.stl"/>
    </geometry>
    <material name="silver">
      <color rgba="1 0 0 1"/>
    </material>
  </visual>
  <collision>
    <origin rpy="0 0 0" xyz="0.1174 0.064996 -0.346995"/>
    <geometry>
      <mesh filename="package://fusion2urdf/ayspot_a0/bin_stl/Hip_F_L_1_m-binary.stl"/>
    </geometry>
  </collision>
</link>
<link name="Upper_F_L_1">
  <inertial>
    <origin rpy="0 0 0" xyz="-3.0000000000002247e-05 -0.04524399999999999 -0.013477000000000017"/>
    <mass value="2.23339"/>
    <inertia ixx="0.00599" ixy="-2e-06" ixz="-0.039498" iyy="0.005386" iyz="0.038501" izz="0.003026"/>
  </inertial>
  <visual>
    <origin rpy="0 0 0" xyz="0.1832 0.086296 -0.346995"/>
    <geometry>
      <mesh filename="package://fusion2urdf/ayspot_a0/bin_stl/Upper_F_L_1_m-binary.stl"/>
    </geometry>
    <material name="silver">
      <color rgba="1 0 0 1"/>
    </material>
  </visual>
  <collision>
    <origin rpy="0 0 0" xyz="0.1832 0.086296 -0.346995"/>
    <geometry>
      <mesh filename="package://fusion2urdf/ayspot_a0/bin_stl/Upper_F_L_1_m-binary.stl"/>
    </geometry>
  </collision>
</link>
<link name="Lower_F_L_1">
  <inertial>
    <origin rpy="0 0 0" xyz="-0.0062540000000000096 -2.0999999999993246e-05 -0.070108"/>
    <mass value="0.539373"/>
    <inertia ixx="0.00264" ixy="0.0" ixz="-0.00159" iyy="0.002688" iyz="0.001556" izz="9.6e-05"/>
  </inertial>
  <visual>
    <origin rpy="0 0 0" xyz="0.183158 0.166126 -0.196941"/>
    <geometry>
      <mesh filename="package://fusion2urdf/ayspot_a0/bin_stl/Lower_F_L_1_m-binary.stl"/>
    </geometry>
    <material name="silver">
      <color rgba="1 0 0 1"/>
    </material>
  </visual>
  <collision>
    <origin rpy="0 0 0" xyz="0.183158 0.166126 -0.196941"/>
    <geometry>
      <mesh filename="package://fusion2urdf/ayspot_a0/bin_stl/Lower_F_L_1_m-binary.stl"/>
    </geometry>
  </collision>
</link>
<link name="Hip_F_R_1">
  <inertial>
    <origin rpy="0 0 0" xyz="-0.04050799999999999 0.0052340000000000025 -5.499999999997174e-05"/>
    <mass value="1.335734"/>
    <inertia ixx="0.001589" ixy="-1.3e-05" ixz="-0.105725" iyy="0.002428" iyz="0.105723" izz="0.0013"/>
  </inertial>
  <visual>
    <origin rpy="0 0 0" xyz="0.1174 -0.064996 -0.346995"/>
    <geometry>
      <mesh filename="package://fusion2urdf/ayspot_a0/bin_stl/Hip_F_R_1_m-binary.stl"/>
    </geometry>
    <material name="silver">
      <color rgba="1 0 0 1"/>
    </material>
  </visual>
  <collision>
    <origin rpy="0 0 0" xyz="0.1174 -0.064996 -0.346995"/>
    <geometry>
      <mesh filename="package://fusion2urdf/ayspot_a0/bin_stl/Hip_F_R_1_m-binary.stl"/>
    </geometry>
  </collision>
</link>
<link name="Upper_F_R_1">
  <inertial>
    <origin rpy="0 0 0" xyz="2.9000000000001247e-05 0.04524399999999999 -0.013477000000000017"/>
    <mass value="2.23339"/>
    <inertia ixx="0.00599" ixy="-2e-06" ixz="-0.233425" iyy="0.005387" iyz="0.234422" izz="0.003026"/>
  </inertial>
  <visual>
    <origin rpy="0 0 0" xyz="0.1832 -0.086296 -0.346995"/>
    <geometry>
      <mesh filename="package://fusion2urdf/ayspot_a0/bin_stl/Upper_F_R_1_m-binary.stl"/>
    </geometry>
    <material name="silver">
      <color rgba="1 0 0 1"/>
    </material>
  </visual>
  <collision>
    <origin rpy="0 0 0" xyz="0.1832 -0.086296 -0.346995"/>
    <geometry>
      <mesh filename="package://fusion2urdf/ayspot_a0/bin_stl/Upper_F_R_1_m-binary.stl"/>
    </geometry>
  </collision>
</link>
<link name="Lower_F_R_1">
  <inertial>
    <origin rpy="0 0 0" xyz="-0.0062540000000000096 -2.1999999999994246e-05 -0.070108"/>
    <mass value="0.539373"/>
    <inertia ixx="0.00264" ixy="0.0" ixz="-0.024326" iyy="0.002688" iyz="0.024291" izz="9.6e-05"/>
  </inertial>
  <visual>
    <origin rpy="0 0 0" xyz="0.183242 -0.166126 -0.196941"/>
    <geometry>
      <mesh filename="package://fusion2urdf/ayspot_a0/bin_stl/Lower_F_R_1_m-binary.stl"/>
    </geometry>
    <material name="silver">
      <color rgba="1 0 0 1"/>
    </material>
  </visual>
  <collision>
    <origin rpy="0 0 0" xyz="0.183242 -0.166126 -0.196941"/>
    <geometry>
      <mesh filename="package://fusion2urdf/ayspot_a0/bin_stl/Lower_F_R_1_m-binary.stl"/>
    </geometry>
  </collision>
</link>
<joint name="旋转4" type="revolute">
  <origin rpy="0 0 0" xyz="0.1124 -0.064996 0.346995"/>
  <parent link="base_link"/>
  <child link="Hip_R_L_1"/>
  <axis xyz="0.01 -0.0 -0.0"/>
  <limit effort="100" lower="-0.698132" upper="0.698132" velocity="100"/>
</joint>
<transmission name="旋转4_tran">
  <type>transmission_interface/SimpleTransmission</type>
  <joint name="旋转4">
    <hardwareInterface>PositionJointInterface</hardwareInterface>
  </joint>
  <actuator name="旋转4_actr">
    <hardwareInterface>PositionJointInterface</hardwareInterface>
    <mechanicalReduction>1</mechanicalReduction>
  </actuator>
</transmission>
<joint name="旋转5" type="revolute">
  <origin rpy="0 0 0" xyz="0.0658 -0.0213 0.0"/>
  <parent link="Hip_R_L_1"/>
  <child link="Upper_R_L_1"/>
  <axis xyz="0.0 -0.01 0.0"/>
  <limit effort="100" lower="-1.570796" upper="1.570796" velocity="100"/>
</joint>
<transmission name="旋转5_tran">
  <type>transmission_interface/SimpleTransmission</type>
  <joint name="旋转5">
    <hardwareInterface>PositionJointInterface</hardwareInterface>
  </joint>
  <actuator name="旋转5_actr">
    <hardwareInterface>PositionJointInterface</hardwareInterface>
    <mechanicalReduction>1</mechanicalReduction>
  </actuator>
</transmission>
<joint name="旋转6" type="revolute">
  <origin rpy="0 0 0" xyz="4.2e-05 -0.07983 -0.150054"/>
  <parent link="Upper_R_L_1"/>
  <child link="Lower_R_L_1"/>
  <axis xyz="-0.0 0.01 0.0"/>
  <limit effort="100" lower="0.0" upper="2.617994" velocity="100"/>
</joint>
<transmission name="旋转6_tran">
  <type>transmission_interface/SimpleTransmission</type>
  <joint name="旋转6">
    <hardwareInterface>PositionJointInterface</hardwareInterface>
  </joint>
  <actuator name="旋转6_actr">
    <hardwareInterface>PositionJointInterface</hardwareInterface>
    <mechanicalReduction>1</mechanicalReduction>
  </actuator>
</transmission>
<joint name="旋转7" type="revolute">
  <origin rpy="0 0 0" xyz="0.1124 0.064996 0.346995"/>
  <parent link="base_link"/>
  <child link="Hip_R_R_1"/>
  <axis xyz="0.01 0.0 0.0"/>
  <limit effort="100" lower="-0.698132" upper="0.698132" velocity="100"/>
</joint>
<transmission name="旋转7_tran">
  <type>transmission_interface/SimpleTransmission</type>
  <joint name="旋转7">
    <hardwareInterface>PositionJointInterface</hardwareInterface>
  </joint>
  <actuator name="旋转7_actr">
    <hardwareInterface>PositionJointInterface</hardwareInterface>
    <mechanicalReduction>1</mechanicalReduction>
  </actuator>
</transmission>
<joint name="旋转8" type="revolute">
  <origin rpy="0 0 0" xyz="0.0658 0.0213 0.0"/>
  <parent link="Hip_R_R_1"/>
  <child link="Upper_R_R_1"/>
  <axis xyz="-0.0 0.01 -0.0"/>
  <limit effort="100" lower="-1.570796" upper="1.570796" velocity="100"/>
</joint>
<transmission name="旋转8_tran">
  <type>transmission_interface/SimpleTransmission</type>
  <joint name="旋转8">
    <hardwareInterface>PositionJointInterface</hardwareInterface>
  </joint>
  <actuator name="旋转8_actr">
    <hardwareInterface>PositionJointInterface</hardwareInterface>
    <mechanicalReduction>1</mechanicalReduction>
  </actuator>
</transmission>
<joint name="旋转9" type="revolute">
  <origin rpy="0 0 0" xyz="-4.2e-05 0.07983 -0.150054"/>
  <parent link="Upper_R_R_1"/>
  <child link="Lower_R_R_1"/>
  <axis xyz="-0.0 -0.01 0.0"/>
  <limit effort="100" lower="-2.617994" upper="0.0" velocity="100"/>
</joint>
<transmission name="旋转9_tran">
  <type>transmission_interface/SimpleTransmission</type>
  <joint name="旋转9">
    <hardwareInterface>PositionJointInterface</hardwareInterface>
  </joint>
  <actuator name="旋转9_actr">
    <hardwareInterface>PositionJointInterface</hardwareInterface>
    <mechanicalReduction>1</mechanicalReduction>
  </actuator>
</transmission>
<joint name="旋转10" type="revolute">
  <origin rpy="0 0 0" xyz="-0.1174 -0.064996 0.346995"/>
  <parent link="base_link"/>
  <child link="Hip_F_L_1"/>
  <axis xyz="0.01 0.0 0.0"/>
  <limit effort="100" lower="-0.698132" upper="0.698132" velocity="100"/>
</joint>
<transmission name="旋转10_tran">
  <type>transmission_interface/SimpleTransmission</type>
  <joint name="旋转10">
    <hardwareInterface>PositionJointInterface</hardwareInterface>
  </joint>
  <actuator name="旋转10_actr">
    <hardwareInterface>PositionJointInterface</hardwareInterface>
    <mechanicalReduction>1</mechanicalReduction>
  </actuator>
</transmission>
<joint name="旋转11" type="revolute">
  <origin rpy="0 0 0" xyz="-0.0658 -0.0213 0.0"/>
  <parent link="Hip_F_L_1"/>
  <child link="Upper_F_L_1"/>
  <axis xyz="0.0 -0.01 -0.0"/>
  <limit effort="100" lower="-1.570796" upper="1.570796" velocity="100"/>
</joint>
<transmission name="旋转11_tran">
  <type>transmission_interface/SimpleTransmission</type>
  <joint name="旋转11">
    <hardwareInterface>PositionJointInterface</hardwareInterface>
  </joint>
  <actuator name="旋转11_actr">
    <hardwareInterface>PositionJointInterface</hardwareInterface>
    <mechanicalReduction>1</mechanicalReduction>
  </actuator>
</transmission>
<joint name="旋转12" type="revolute">
  <origin rpy="0 0 0" xyz="4.2e-05 -0.07983 -0.150054"/>
  <parent link="Upper_F_L_1"/>
  <child link="Lower_F_L_1"/>
  <axis xyz="-0.0 0.01 0.0"/>
  <limit effort="100" lower="0.0" upper="2.617994" velocity="100"/>
</joint>
<transmission name="旋转12_tran">
  <type>transmission_interface/SimpleTransmission</type>
  <joint name="旋转12">
    <hardwareInterface>PositionJointInterface</hardwareInterface>
  </joint>
  <actuator name="旋转12_actr">
    <hardwareInterface>PositionJointInterface</hardwareInterface>
    <mechanicalReduction>1</mechanicalReduction>
  </actuator>
</transmission>
<joint name="旋转13" type="revolute">
  <origin rpy="0 0 0" xyz="-0.1174 0.064996 0.346995"/>
  <parent link="base_link"/>
  <child link="Hip_F_R_1"/>
  <axis xyz="0.01 0.0 0.0"/>
  <limit effort="100" lower="-0.698132" upper="0.698132" velocity="100"/>
</joint>
<transmission name="旋转13_tran">
  <type>transmission_interface/SimpleTransmission</type>
  <joint name="旋转13">
    <hardwareInterface>PositionJointInterface</hardwareInterface>
  </joint>
  <actuator name="旋转13_actr">
    <hardwareInterface>PositionJointInterface</hardwareInterface>
    <mechanicalReduction>1</mechanicalReduction>
  </actuator>
</transmission>
<joint name="旋转14" type="revolute">
  <origin rpy="0 0 0" xyz="-0.0658 0.0213 0.0"/>
  <parent link="Hip_F_R_1"/>
  <child link="Upper_F_R_1"/>
  <axis xyz="-0.0 0.01 0.0"/>
  <limit effort="100" lower="-1.570796" upper="1.570796" velocity="100"/>
</joint>
<transmission name="旋转14_tran">
  <type>transmission_interface/SimpleTransmission</type>
  <joint name="旋转14">
    <hardwareInterface>PositionJointInterface</hardwareInterface>
  </joint>
  <actuator name="旋转14_actr">
    <hardwareInterface>PositionJointInterface</hardwareInterface>
    <mechanicalReduction>1</mechanicalReduction>
  </actuator>
</transmission>
<joint name="旋转15" type="revolute">
  <origin rpy="0 0 0" xyz="-4.2e-05 0.07983 -0.150054"/>
  <parent link="Upper_F_R_1"/>
  <child link="Lower_F_R_1"/>
  <axis xyz="-0.0 -0.01 0.0"/>
  <limit effort="100" lower="-2.617994" upper="0.0" velocity="100"/>
</joint>
<transmission name="旋转15_tran">
  <type>transmission_interface/SimpleTransmission</type>
  <joint name="旋转15">
    <hardwareInterface>PositionJointInterface</hardwareInterface>
  </joint>
  <actuator name="旋转15_actr">
    <hardwareInterface>PositionJointInterface</hardwareInterface>
    <mechanicalReduction>1</mechanicalReduction>
  </actuator>
</transmission>
<gazebo>
  <plugin filename="libgazebo_ros_control.so" name="control"/>
</gazebo>
</robot>
